# 异常处理：别让自己在出问题的时候变为瞎子

https://time.geekbang.org/column/article/220230



## 提交线程池的任务出了异常会怎么样？

把任务提交到线程池处理，任务本身出现异常时会怎样呢？

```java

@GetMapping("execute")
public void execute() throws InterruptedException {

    String prefix = "test";
    ExecutorService threadPool = Executors.newFixedThreadPool(1, new ThreadFactoryBuilder().setNameFormat(prefix+"%d").get());
    //提交10个任务到线程池处理，第5个任务会抛出运行时异常
    IntStream.rangeClosed(1, 10).forEach(i -> threadPool.execute(() -> {
        if (i == 5) throw new RuntimeException("error");
        log.info("I'm done : {}", i);
    }));

    threadPool.shutdown();
    threadPool.awaitTermination(1, TimeUnit.HOURS);
}
```

观察日志可以发现两点：

```

...
[14:33:55.990] [test0] [INFO ] [e.d.ThreadPoolAndExceptionController:26  ] - I'm done : 4
Exception in thread "test0" java.lang.RuntimeException: error
  at org.geekbang.time.commonmistakes.exception.demo3.ThreadPoolAndExceptionController.lambda$null$0(ThreadPoolAndExceptionController.java:25)
  at java.util.concurrent.ThreadPoolExecutor.runWorker(ThreadPoolExecutor.java:1149)
  at java.util.concurrent.ThreadPoolExecutor$Worker.run(ThreadPoolExecutor.java:624)
  at java.lang.Thread.run(Thread.java:748)
[14:33:55.990] [test1] [INFO ] [e.d.ThreadPoolAndExceptionController:26  ] - I'm done : 6
...
```

- **从线程名的改变可以知道因为异常的抛出老线程退出了，线程池只能重新创建一个线程**。如果每个异步任务都以异常结束，那么线程池可能完全起不到线程重用的作用
- 因为没有手动捕获异常进行处理，ThreadGroup 帮我们进行了未捕获异常的默认处理，向标准错误输出打印了出现异常的线程名称和异常信息**。显然，这种没有以统一的错误日志格式记录错误信息打印出来的形式，对生产级代码是不合适的**

如何修复？

1、以 execute 方法提交到线程池的异步任务，最好在任务内部做好异常处理；

2、设置自定义的异常处理程序作为保底，比如在声明线程池时自定义线程池的未捕获异常处理程序

```java
// 设置自定义线程未捕获异常的处理方式

new ThreadFactoryBuilder()
  .setNameFormat(prefix+"%d")
  .setUncaughtExceptionHandler((thread, throwable)-> log.error("ThreadPool {} got exception", thread, throwable))
  .get()
```

设置全局异常捕获

```java

static {
    Thread.setDefaultUncaughtExceptionHandler((thread, throwable)-> log.error("Thread {} got exception", thread, throwable));
}
```

**那么，把 execute 方法改为 submit，线程还会退出吗，异常还能被处理程序捕获到吗？**

submit 方法会返回一个Futrue作为返回值，可以通过Futrue.get()获取异步任务的返回值。(使用Submit提交任务，出现异常不会被抛出，会被吃掉，在使用get方法获取返回值时才会被抛出来)

修改代码后重新执行程序可以看到如下日志，说明线程没退出，异常也没记录被生吞了：

```java

[15:44:33.769] [test0] [INFO ] [e.d.ThreadPoolAndExceptionController:47  ] - I'm done : 1
[15:44:33.770] [test0] [INFO ] [e.d.ThreadPoolAndExceptionController:47  ] - I'm done : 2
[15:44:33.770] [test0] [INFO ] [e.d.ThreadPoolAndExceptionController:47  ] - I'm done : 3
[15:44:33.770] [test0] [INFO ] [e.d.ThreadPoolAndExceptionController:47  ] - I'm done : 4
[15:44:33.770] [test0] [INFO ] [e.d.ThreadPoolAndExceptionController:47  ] - I'm done : 6
[15:44:33.770] [test0] [INFO ] [e.d.ThreadPoolAndExceptionController:47  ] - I'm done : 7
[15:44:33.770] [test0] [INFO ] [e.d.ThreadPoolAndExceptionController:47  ] - I'm done : 8
[15:44:33.771] [test0] [INFO ] [e.d.ThreadPoolAndExceptionController:47  ] - I'm done : 9
[15:44:33.771] [test0] [INFO ] [e.d.ThreadPoolAndExceptionController:47  ] - I'm done : 10
```

查看 FutureTask 源码可以发现，在执行任务出现异常之后，异常存到了一个 outcome 字段中，只有在调用 get 方法获取 FutureTask 结果的时候，才会以 ExecutionException 的形式重新抛出异常：

```java

public void run() {
...
    try {
        Callable<V> c = callable;
        if (c != null && state == NEW) {
            V result;
            boolean ran;
            try {
                result = c.call();
                ran = true;
            } catch (Throwable ex) {
                result = null;
                ran = false;
                setException(ex);
            }
...
}

protected void setException(Throwable t) {
    if (UNSAFE.compareAndSwapInt(this, stateOffset, NEW, COMPLETING)) {
        outcome = t;
        UNSAFE.putOrderedInt(this, stateOffset, EXCEPTIONAL); // final state
        finishCompletion();
    }
}

public V get() throws InterruptedException, ExecutionException {
    int s = state;
    if (s <= COMPLETING)
        s = awaitDone(false, 0L);
    return report(s);
}

private V report(int s) throws ExecutionException {
    Object x = outcome;
    if (s == NORMAL)
        return (V)x;
    if (s >= CANCELLED)
        throw new CancellationException();
    throw new ExecutionException((Throwable)x);
}
```

我们把 submit 返回的 Future 放到了 List 中，随后遍历 List 来捕获所有任务的异常。这么做确实合乎情理。**既然是以 submit 方式来提交任务，那么我们应该关心任务的执行结果，否则应该以 execute 来提交任务**

```java

List<Future> tasks = IntStream.rangeClosed(1, 10).mapToObj(i -> threadPool.submit(() -> {
    if (i == 5) throw new RuntimeException("error");
    log.info("I'm done : {}", i);
})).collect(Collectors.toList());

tasks.forEach(task-> {
    try {
        task.get();
    } catch (Exception e) {
        log.error("Got exception", e);
    }
});
```

```

[15:44:13.543] [http-nio-45678-exec-1] [ERROR] [e.d.ThreadPoolAndExceptionController:69  ] - Got exception
java.util.concurrent.ExecutionException: java.lang.RuntimeException: error
```



## 重点

- 注意捕获和处理异常的最佳实践。首先，不应该用 AOP 对所有方法进行统一异常处理，异常要么不捕获不处理，要么根据不同的业务逻辑、不同的异常类型进行精细化、针对性处理；其次，处理异常应该杜绝生吞，并确保异常栈信息得到保留；最后，如果需要重新抛出异常的话，请使用具有意义的异常类型和异常消息
- 务必小心 finally 代码块中资源回收逻辑，确保 finally 代码块不出现异常，内部把异常处理完毕，避免 finally 中的异常覆盖 try 中的异常；或者考虑使用 addSuppressed 方法把 finally 中的异常附加到 try 中的异常上，确保主异常信息不丢失。此外，使用实现了 AutoCloseable 接口的资源，务必使用 try-with-resources 模式来使用资源，确保资源可以正确释放，也同时确保异常可以正确处理。
- 虽然在统一的地方定义收口所有的业务异常是一个不错的实践，但务必确保异常是每次 new 出来的，而不能使用一个预先定义的 static 字段存放异常，否则可能会引起栈信息的错乱。
- 确保正确处理了线程池中任务的异常，如果任务通过 execute 提交，那么出现异常会导致线程退出，大量的异常会导致线程重复创建引起性能问题，我们应该尽可能确保任务不出异常，同时设置默认的未捕获异常处理程序来兜底；如果任务通过 submit 提交意味着我们关心任务的执行结果，应该通过拿到的 Future 调用其 get 方法来获得任务运行结果和可能出现的异常，否则异常可能就被生吞了



## 思考

1、关于在 finally 代码块中抛出异常的坑，如果在 finally 代码块中返回值，你觉得程序会以 try 或 catch 中返回值为准，还是以 finally 中的返回值为准呢？

以finally语句块为准（**对于finally中的代码块其实是复制到try和catch中的return和throw之前的方式来处理的**，**所以一定是最后执行的**）

JVM 处理try catch 的原理：**JVM采用异常表控制try-catch的跳转逻辑**

首先需要明白的是在编译生成的字节码中，**每个方法都附带一个异常表**。异常表中的每一个条目代表一个异常处理器，并且由 from 指针、to 指针、target 指针以及所捕获的异常类型构成。这些指针的值是字节码索引（bytecode index，bci），用以定位字节码。其中，from 指针和 to 指针标示了该异常处理器所监控的范围，例如 try 代码块所覆盖的范围。target 指针则指向异常处理器的起始位置，例如 catch 代码块的起始位置；
当程序触发异常时，Java 虚拟机会从上至下遍历异常表中的所有条目。当触发异常的字节码的索引值在某个异常表条目的监控范围内，Java 虚拟机会判断所抛出的异常和该条目想要捕获的异常是否匹配。如果匹配，Java 虚拟机会将控制流转移至该条目 target 指针指向的字节码。如果遍历完所有异常表条目，Java 虚拟机仍未匹配到异常处理器，那么它会弹出当前方法对应的 Java 栈帧，并且在调用者（caller）中重复上述操作。在最坏情况下，Java 虚拟机需要遍历当前线程 Java 栈上所有方法的异常表。所以异常操作是一个非常耗费性能的操作；
finally 代码块的原理是复制 finally 代码块的内容，分别放在 try-catch 代码块所有正常执行路径以及异常执行路径的出口中。所以不管是是正常还是异常执行，finally都是最后执行的，所以肯定是finally语句块中为准。